Workbook

Sheet Inicio
C4: Importaciones de gas natural por puntos de entrada
C9: Fuente/Notas | D9: 2004-marzo 2009 | E9: Anejos de la Resolución del 15 de Julio de 2002
D10: abril 2009-actualidad | E10: Anejos de la Resolución del 15 de diciembre 2008
D11: Desde octubre 2014 | E11: De conformidad con la normativa europea, se agrupan las interconexiones en VIP Ibérico (Badajoz, Tuy y VIP Portugal) y VIP Pirineos (Irún y Larrau)
D12: enero 2015-actualidad | E12: Por adaptación a la legislación europea, desde enero de 2015, desaparece el concepto de contrato de tránsito de gas, tratándose en adelante como una importación y una exportación más. En consecuencia los datos de 2014 y 2015 no siempre son comparables.
D13: ^ mayor que 0
A16: Actualizado el 17-08-2026 | G16: Para más información: cores.institucional@cores.es. Tlf.: +34 91 360 09 10, o visite: www.cores.es

Sheet Conexiones Internacionales
C3: =Inicio!C4 -> Importaciones de gas natural por puntos de entrada
A4: =Inicio!$A$16 -> Actualizado el 17-08-2026 | K4: Unidad: gigavatio hora
C5: Conexiones Internacionales
A6: Año | B6: Mes | C6: Almería | D6: Badajoz | E6: Irún | F6: Larrau | G6: Tuy | H6: Zahara de los Atunes | I6: VIP Ibérico | J6: VIP Pirineos | K6: Total Conexiones internacionales
A7: 2004 | B7: enero | C7: 0 | D7: 0 | E7: 0 | F7: 2153.959 | G7: 0 | H7: 6511.869 | I7: 0 | K7: 8665.828
A8: 2004 | B8: febrero | C8: 0 | D8: 0 | E8: 0 | F8: 2191.2503 | G8: 337.27 | H8: 7179.018 | I8: 0 | K8: 9707.5383
A9: 2004 | B9: marzo | C9: 0 | D9: 0 | E9: 0 | F9: 2304.193 | G9: 337.64 | H9: 8231.717 | I9: 0 | K9: 10873.55
A10: 2004 | B10: abril | C10: 0 | D10: 0 | E10: 0 | F10: 2197.153 | G10: 0 | H10: 5275.398 | I10: 0 | K10: 7472.551
A11: 2004 | B11: mayo | C11: 0 | D11: 0 | E11: 0 | F11: 2262.6332 | G11: 232.6 | H11: 5316.899 | I11: 0 | K11: 7812.1322
A12: 2004 | B12: junio | C12: 0 | D12: 0 | E12: 0 | F12: 2205.3343 | G12: 0 | H12: 6180.6113 | I12: 0 | K12: 8385.9456
A13: 2004 | B13: julio | C13: 0 | D13: 0 | E13: 0 | F13: 2131.28 | G13: 0 | H13: 6711.922 | I13: 0 | K13: 8843.202
A14: 2004 | B14: agosto | C14: 0 | D14: 0 | E14: 0 | F14: 1702.126 | G14: 0 | H14: 5878.535 | I14: 0 | K14: 7580.661
A15: 2004 | B15: septiembre | C15: 0 | D15: 0 | E15: 0 | F15: 2160.5165 | G15: 0 | H15: 7299.796 | I15: 0 | K15: 9460.3125
A16: 2004 | B16: octubre | C16: 0 | D16: 0 | E16: 0 | F16: 2355.4397 | G16: 0 | H16: 8175.158 | I16: 0 | K16: 10530.598
A17: 2004 | B17: noviembre | C17: 0 | D17: 0 | E17: 0 | F17: 2279.0174 | G17: 0 | H17: 9134.514 | I17: 0 | K17: 11413.531
A18: 2004 | B18: diciembre | C18: 0 | D18: 0 | E18: 0 | F18: 2349.9121 | G18: 0 | H18: 8244.63 | I18: 0 | K18: 10594.542
... A135: 2013 | B135: diciembre | C135: 6829.623 | D135: 0 | E135: 0 | F135: 4691.419 | G135: 0 | H135: 7763.707 | I135: 24.64625 | K135: 19309.395
A136: 2013 | B136: total | C136: 70174.003 | D136: 1437.8288 | E136: 1856.6436 | F136: 42446.088 | G136: 0 | H136: 85189.941 | I136: 478.63877 | J136: 0 | K136: 201583.14
A137: 2014 | B137: enero | C137: 6976.1964 | D137: 0 | E137: 0 | F137: 3546.92 | G137: 0 | H137: 7759.2386 | I137: 157.34804 | J137: 0 | K137: 18439.703
A138: 2014 | B138: febrero | C138: 6480.3885 | D138: 0 | E138: 0 | F138: 4179.5659 | G138: 0 | H138: 7495.2864 | I138: 0 | J138: 0 | K138: 18155.241
A139: 2014 | B139: marzo | C139: 6885.6757 | D139: 0 | E139: 0 | F139: 3811.2181 | G139: 0 | H139: 7678.7892 | I139: 0 | J139: 0 | K139: 18375.683
A140: 2014 | B140: abril | C140: 6105.5317 | D140: 0 | E140: 299.70069 | F140: 3187.5067 | G140: 0 | H140: 6021.1013 | I140: 0 | J140: 0 | K140: 15613.84
A141: 2014 | B141: mayo | C141: 5861.7961 | D141: 0 | E141: 303.14809 | F141: 3737.7099 | G141: 0 | H141: 6341.1698 | I141: 0 | J141: 0 | K141: 16243.824
A142: 2014 | B142: junio | C142: 6132.95 | D142: 0 | E142: 298.19903 | F142: 3080.252 | G142: 0 | H142: 7010.5872 | I142: 0 | J142: 0 | K142: 16521.988
A143: 2014 | B143: julio | C143: 4622.0045 | D143: 0 | E143: 300.9225 | F143: 3945.8859 | G143: 0 | H143: 7694.4964 | I143: 0 | J143: 0 | K143: 16563.309
A144: 2014 | B144: agosto | C144: 4428.0447 | D144: 0 | E144: 310.00001 | F144: 4123.1274 | G144: 0 | H144: 5580.4077 | I144: 0 | J144: 0 | K144: 14441.58
A145: 2014 | B145: septiembre | C145: 5991.8244 | D145: 0 | E145: 297.08839 | F145: 3852.6424 | G145: 0 | H145: 6621.9341 | I145: 0 | J145: 0 | K145: 16763.489
A146: 2014 | B146: octubre | C146: 6752.8634 | D146: 0 | E146: 0 | G146: 0 | H146: 7043.3579 | I146: 0 | J146: 4522.2619 | K146: 18318.483
A147: 2014 | B147: noviembre | C147: 6240.5615 | D147: 0 | E147: 0 | G147: 0 | H147: 7299.4047 | I147: 0 | J147: 4584.7276 | K147: 18124.694
A148: 2014 | B148: diciembre | C148: 6301.7623 | D148: 0 | E148: 0 | G148: 0 | H148: 5230.7806 | I148: 0 | J148: 4785.599 | K148: 16318.142
A149: 2014 | B149: total | C149: 72779.599 | D149: 0 | E149: 1809.0587 | F149: 33464.828 | G149: 0 | H149: 81776.554 | I149: 157.34804 | J149: 13892.588 | K149: 203879.98
A150: 2015 | B150: enero | C150: 6203.462 | D150: 0 | E150: 0 | G150: 0 | H150: 10041.453 | I150: 0 | J150: 4148.0211 | K150: 20392.936
A151: 2015 | B151: febrero | C151: 4889.6241 | D151: 0 | E151: 0 | G151: 0 | H151: 6236.6941 | I151: 0 | J151: 3740.9843 | K151: 14867.302
A152: 2015 | B152: marzo | C152: 4534.921 | D152: 0 | E152: 0 | G152: 0 | H152: 4567.5333 | I152: 0 | J152: 3583.6126 | K152: 12686.067
A153: 2015 | B153: abril | C153: 6389.1113 | D153: 0 | E153: 0 | G153: 0 | H153: 9551.3142 | I153: 0 | J153: 2290.9767 | K153: 18231.402
A154: 2015 | B154: mayo | C154: 5797.6096 | D154: 0 | E154: 0 | G154: 0 | H154: 7533.0544 | I154: 0 | J154: 2774.076 | K154: 16104.74
A155: 2015 | B155: junio | C155: 5960.2508 | D155: 0 | E155: 0 | G155: 0 | H155: 6580.8459 | I155: 0 | J155: 2211.2034 | K155: 14752.3
A156: 2015 | B156: julio | C156: 6590.7868 | D156: 0 | E156: 0 | G156: 0 | H156: 9683.2775 | I156: 0 | J156: 2727.0777 | K156: 19001.142
A157: 2015 | B157: agosto | C157: 6928.1672 | D157: 0 | E157: 0 | G157: 0 | H157: 9520.1653 | I157: 0 | J157: 2893.9222 | K157: 19342.255
A158: 2015 | B158: septiembre | C158: 6400.0582 | D158: 0 | E158: 0 | G158: 0 | H158: 8352.5317 | I158: 0 | J158: 2802.8238 | K158: 17555.414
...

Sheet Plantas regasif. y cisternas
C3: =Inicio!C4 -> Importaciones de gas natural por puntos de entrada
A4: =Inicio!$A$16 -> Actualizado el 17-08-2026 | L4: Unidad: gigavatio hora
C5: Plantas de regasificación | L5: Cisternas
A6: Año | B6: Mes | C6: Barcelona | D6: Bilbao | E6: Cartagena | F6: Huelva | G6: Mugardos | H6: Musel | I6: Sagunto | J6: Total Plantas de regasificación | L6: Cisternas
A7: 2004 | B7: enero | C7: 7042.0879 | D7: 2719.8668 | E7: 5274.8376 | F7: 2455.7904 | G7: 0 | I7: 0 | J7: 17492.583 | L7: 0
A8: 2004 | B8: febrero | C8: 6558.9904 | D8: 1690.365 | E8: 4369.4843 | F8: 2769.7185 | G8: 0 | I8: 0 | J8: 15388.558 | L8: 0
A9: 2004 | B9: marzo | C9: 4743.2996 | D9: 1695.844 | E9: 5005.5314 | F9: 3617.8601 | G9: 0 | I9: 0 | J9: 15062.535 | L9: 0
A10: 2004 | B10: abril | C10: 5615.8864 | D10: 2069.697 | E10: 4695.3481 | F10: 3372.7636 | G10: 0 | I10: 0 | J10: 15753.695 | L10: 0
A11: 2004 | B11: mayo | C11: 6295.785 | D11: 3064.4903 | E11: 6677.6866 | F11: 3388.6596 | G11: 0 | I11: 0 | J11: 19426.621 | L11: 0
A12: 2004 | B12: junio | C12: 6126.1201 | D12: 2260.4467 | E12: 5057.4653 | F12: 3085.4081 | G12: 0 | I12: 0 | J12: 16529.44 | L12: 0
A13: 2004 | B13: julio | C13: 5135.5693 | D13: 2091.4941 | E13: 5734.065 | F13: 4405.82 | G13: 0 | I13: 0 | J13: 17366.948 | L13: 0
A14: 2004 | B14: agosto | C14: 4642.0599 | D14: 2214.9405 | E14: 5230.946 | F14: 3690.7909 | G14: 0 | I14: 0 | J14: 15778.737 | L14: 0
A15: 2004 | B15: septiembre | C15: 5366.7164 | D15: 3298.4671 | E15: 6277.6253 | F15: 3669.2918 | G15: 0 | I15: 0 | J15: 18612.101 | L15: 0
A16: 2004 | B16: octubre | C16: 6147.2017 | D16: 3092.6594 | E16: 4179.924 | F16: 2776.6181 | G16: 0 | I16: 0 | J16: 16196.403 | L16: 0
A17: 2004 | B17: noviembre | C17: 6666.7459 | D17: 3453.9217 | E17: 5186.9542 | F17: 4241.4173 | G17: 0 | I17: 0 | J17: 19549.039 | L17: 0
A18: 2004 | B18: diciembre | C18: 5198.9915 | D18: 1702.5627 | E18: 6739.4229 | F18: 2556.5744 | G18: 0 | I18: 0 | J18: 16197.551 | L18: 0
... A214: 2019 | B214: total | C214: 62126.886 | D214: 65382.172 | E214: 19984.417 | F214: 55563.81 | G214: 13777.381 | I214: 23643.69 | J214: 240478.36 | L214: 395.046
A215: 2020 | B215: enero | C215: 5655.2411 | D215: 7094.9221 | E215: 3147.113 | F215: 4450.6312 | G215: 837.68517 | H215: 0 | I215: 0 | J215: 21185.593 | L215: 48.154
A216: 2020 | B216: febrero | C216: 3693.755 | D216: 5810.8027 | E216: 3940.5707 | F216: 5269.6418 | G216: 0 | H216: 0 | I216: 559.64015 | J216: 19274.41 | L216: 48.688
A217: 2020 | B217: marzo | C217: 5788.4115 | D217: 6159.8778 | E217: 4045.219 | F217: 6209.0407 | G217: 1101.6704 | H217: 0 | I217: 889.436 | J217: 24193.655 | L217: 32.631
A218: 2020 | B218: abril | C218: 2852.7993 | D218: 4879.206 | E218: 1822.7523 | F218: 1863.4396 | G218: 1949.1082 | H218: 0 | I218: 2287.6473 | J218: 15654.953 | L218: 11.543
A219: 2020 | B219: mayo | C219: 2991.632 | D219: 5297.9681 | E219: 2860.5837 | F219: 3831.8475 | G219: 1940.6261 | H219: 0 | I219: 2845.3862 | J219: 19768.044 | L219: 10.393
A220: 2020 | B220: junio | C220: 3433.7665 | D220: 4921.8609 | E220: 3344.1239 | F220: 3312.9188 | G220: 3075.8199 | H220: 0 | I220: 995.10029 | J220: 19083.59 | L220: 0
A221: 2020 | B221: julio | C221: 6871.4574 | D221: 3953.8212 | E221: 3528.2296 | F221: 4692.2733 | G221: 1096.1768 | H221: 0 | I221: 2473.2338 | J221: 22615.192 | L221: 14.269
A222: 2020 | B222: agosto | C222: 3701.3301 | D222: 5871.7432 | E222: 3930.7369 | F222: 4736.9893 | G222: 2006.0648 | H222: 0 | I222: 2393.209 | J222: 22640.073 | L222: 27.442
A223: 2020 | B223: septiembre | C223: 4808.5654 | D223: 4701.0496 | E223: 1936.0617 | F223: 3705.4547 | G223: 2030.0712 | H223: 0 | I223: 2932.8922 | J223: 20114.095 | L223: 12.771
A224: 2020 | B224: octubre | C224: 879.65722 | D224: 3058.8533 | E224: 2755.4055 | F224: 4080.2777 | G224: 1989.3583 | H224: 0 | I224: 496.16288 | J224: 13259.715 | L224: 0
A225: 2020 | B225: noviembre | C225: 1873.6956 | D225: 4093.9429 | E225: 979.38792 | F225: 2849.0843 | G225: 2916.0175 | H225: 0 | I225: 2156.3047 | J225: 14868.433 | L225: 17.843
A226: 2020 | B226: diciembre | C226: 3382.0441 | D226: 1939.4013 | E226: 1927.1528 | F226: 4102.7296 | G226: 2682.8256 | H226: 0 | I226: 2043.4445 | J226: 16077.598 | L226: 0
... A298: 2026 | B298: junio | C298: 1558.8881 | D298: 3299.3053 | E298: 1882.0888 | F298: 2173.3646 | G298: 2132.4974 | H298: 1060.1479 | I298: 1065.3964 | J298: 13171.688 | L298: 0
C299: 0 | D299: 0 | E299: 0 | F299: 0 | G299: 0 | H299: 0 | I299: 0 | J299: 0 | L299: 0
C300: 0 | D300: 0 | E300: 0 | F300: 0 | G300: 0 | H300: 0 | I300: 0 | J300: 0 | L300: 0
C301: 0 | D301: 0 | E301: 0 | F301: 0 | G301: 0 | H301: 0 | I301: 0 | J301: 0 | L301: 0
C302: 0 | D302: 0 | E302: 0 | F302: 0 | G302: 0 | H302: 0 | I302: 0 | J302: 0 | L302: 0
C303: 0 | D303: 0 | E303: 0 | F303: 0 | G303: 0 | H303: 0 | I303: 0 | J303: 0 | L303: 0
C304: 0 | D304: 0 | E304: 0 | F304: 0 | G304: 0 | H304: 0 | I304: 0 | J304: 0 | L304: 0

Sheet Todos
C3: =Inicio!C4 -> Importaciones de gas natural por puntos de entrada
A4: =Inicio!$A$16 -> Actualizado el 17-08-2026 | Z4: Unidad: gigavatio hora
C5: ='Conexiones Internacionales'!C5:K5 -> Conexiones Internacionales | M5: Plantas de regasificación | V5: Cisternas | X5: Total | Y5: Total GNL | Z5: Total GN
A6: Año | B6: Mes | C6: ='Conexiones Internacionales'!C6 -> Almería | D6: ='Conexiones Internacionales'!D6 -> Badajoz | E6: ='Conexiones Internacionales'!E6 -> Irún | F6: ='Conexiones Internacionales'!F6 -> Larrau | G6: ='Conexiones Internacionales'!G6 -> Tuy | H6: ='Conexiones Internacionales'!H6 -> Zahara de los Atunes | I6: ='Conexiones Internacionales'!I6 -> VIP Ibérico | J6: ='Conexiones Internacionales'!J6 -> VIP Pirineos | K6: ='Conexiones Internacionales'!K6 -> Total Conexiones internacionales | M6: ='Plantas regasif. y cisternas'!C6 -> Barcelona | N6: ='Plantas regasif. y cisternas'!D6 -> Bilbao | O6: ='Plantas regasif. y cisternas'!E6 -> Cartagena | P6: ='Plantas regasif. y cisternas'!F6 -> Huelva | Q6: ='Plantas regasif. y cisternas'!G6 -> Mugardos | R6: Musel | S6: ='Plantas regasif. y cisternas'!I6 -> Sagunto | T6: ='Plantas regasif. y cisternas'!J6 -> Total Plantas de regasificación | V6: ='Plantas regasif. y cisternas'!L6 -> Cisternas | Y6: Total GNL | Z6: Total GN
A7: 2004 | B7: enero | C7: 0 | D7: 0 | E7: 0 | F7: 2153.959 | G7: 0 | H7: 6511.869 | I7: 0 | J7: 0 | K7: 8665.828 | M7: 7042.0879 | N7: 2719.8668 | O7: 5274.8376 | P7: 2455.7904 | Q7: 0 | S7: 0 | T7: 17492.583 | V7: 0 | X7: 26158.411 | Y7: 17492.583 | Z7: 8665.828
A8: 2004 | B8: febrero | C8: 0 | D8: 0 | E8: 0 | F8: 2191.2503 | G8: 337.27 | H8: 7179.018 | I8: 0 | J8: 0 | K8: 9707.5383 | M8: 6558.9904 | N8: 1690.365 | O8: 4369.4843 | P8: 2769.7185 | Q8: 0 | S8: 0 | T8: 15388.558 | V8: 0 | X8: 25096.097 | Y8: 15388.558 | Z8: 9707.5383
A9: 2004 | B9: marzo | C9: 0 | D9: 0 | E9: 0 | F9: 2304.193 | G9: 337.64 | H9: 8231.717 | I9: 0 | J9: 0 | K9: 10873.55 | M9: 4743.2996 | N9: 1695.844 | O9: 5005.5314 | P9: 3617.8601 | Q9: 0 | S9: 0 | T9: 15062.535 | V9: 0 | X9: 25936.085 | Y9: 15062.535 | Z9: 10873.55
A10: 2004 | B10: abril | C10: 0 | D10: 0 | E10: 0 | F10: 2197.153 | G10: 0 | H10: 5275.398 | I10: 0 | J10: 0 | K10: 7472.551 | M10: 5615.8864 | N10: 2069.697 | O10: 4695.3481 | P10: 3372.7636 | Q10: 0 | S10: 0 | T10: 15753.695 | V10: 0 | X10: 23226.246 | Y10: 15753.695 | Z10: 7472.551
A11: 2004 | B11: mayo | C11: 0 | D11: 0 | E11: 0 | F11: 2262.6332 | G11: 232.6 | H11: 5316.899 | I11: 0 | J11: 0 | K11: 7812.1322 | M11: 6295.785 | N11: 3064.4903 | O11: 6677.6866 | P11: 3388.6596 | Q11: 0 | S11: 0 | T11: 19426.621 | V11: 0 | X11: 27238.754 | Y11: 19426.621 | Z11: 7812.1322
A12: 2004 | B12: junio | C12: 0 | D12: 0 | E12: 0 | F12: 2205.3343 | G12: 0 | H12: 6180.6113 | I12: 0 | J12: 0 | K12: 8385.9456 | M12: 6126.1201 | N12: 2260.4467 | O12: 5057.4653 | P12: 3085.4081 | Q12: 0 | S12: 0 | T12: 16529.44 | V12: 0 | X12: 24915.386 | Y12: 16529.44 | Z12: 8385.9456
A13: 2004 | B13: julio | C13: 0 | D13: 0 | E13: 0 | F13: 2131.28 | G13: 0 | H13: 6711.922 | I13: 0 | J13: 0 | K13: 8843.202 | M13: 5135.5693 | N13: 2091.4941 | O13: 5734.065 | P13: 4405.82 | Q13: 0 | S13: 0 | T13: 17366.948 | V13: 0 | X13: 26210.15 | Y13: 17366.948 | Z13: 8843.202
A14: 2004 | B14: agosto | C14: 0 | D14: 0 | E14: 0 | F14: 1702.126 | G14: 0 | H14: 5878.535 | I14: 0 | J14: 0 | K14: 7580.661 | M14: 4642.0599 | N14: 2214.9405 | O14: 5230.946 | P14: 3690.7909 | Q14: 0 | S14: 0 | T14: 15778.737 | V14: 0 | X14: 23359.398 | Y14: 15778.737 | Z14: 7580.661
A15: 2004 | B15: septiembre | C15: 0 | D15: 0 | E15: 0 | F15: 2160.5165 | G15: 0 | H15: 7299.796 | I15: 0 | J15: 0 | K15: 9460.3125 | M15: 5366.7164 | N15: 3298.4671 | O15: 6277.6253 | P15: 3669.2918 | Q15: 0 | S15: 0 | T15: 18612.101 | V15: 0 | X15: 28072.413 | Y15: 18612.101 | Z15: 9460.3125
A16: 2004 | B16: octubre | C16: 0 | D16: 0 | E16: 0 | F16: 2355.4397 | G16: 0 | H16: 8175.158 | I16: 0 | J16: 0 | K16: 10530.598 | M16: 6147.2017 | N16: 3092.6594 | O16: 4179.924 | P16: 2776.6181 | Q16: 0 | S16: 0 | T16: 16196.403 | V16: 0 | X16: 26727.001 | Y16: 16196.403 | Z16: 10530.598
A17: 2004 | B17: noviembre | C17: 0 | D17: 0 | E17: 0 | F17: 2279.0174 | G17: 0 | H17: 9134.514 | I17: 0 | J17: 0 | K17: 11413.531 | M17: 6666.7459 | N17: 3453.9217 | O17: 5186.9542 | P17: 4241.4173 | Q17: 0 | S17: 0 | T17: 19549.039 | V17: 0 | X17: 30962.571 | Y17: 19549.039 | Z17: 11413.531
A18: 2004 | B18: diciembre | C18: 0 | D18: 0 | E18: 0 | F18: 2349.9121 | G18: 0 | H18: 8244.63 | I18: 0 | J18: 0 | K18: 10594.542 | M18: 5198.9915 | N18: 1702.5627 | O18: 6739.4229 | P18: 2556.5744 | Q18: 0 | S18: 0 | T18: 16197.551 | V18: 0 | X18: 26792.094 | Y18: 16197.551 | Z18: 10594.542
... A123: 2012 | B123: total | C123: 38803.897 | D123: 3220.2 | E123: 1532.239 | F123: 33745.456 | G123: 0 | H123: 79764.388 | I123: 0 | J123: 0 | K123: 157066.18 | M123: 60742.279 | N123: 40092.226 | O123: 37718.63 | P123: 48218.291 | Q123: 20487.025 | S123: 30470.062 | T123: 237728.51 | V123: 0 | X123: 394794.69 | Y123: 237728.51 | Z123: 157066.18
A124: 2013 | B124: enero | C124: 5065.464 | D124: 117.5 | E124: 0 | F124: 3083.4279 | G124: 0 | H124: 8573.7878 | I124: 0 | K124: 16840.18 | M124: 6049.1904 | N124: 2635.546 | O124: 1601.3956 | P124: 3627.4863 | Q124: 1672.3426 | S124: 1759.854 | T124: 17345.815 | V124: 0 | X124: 34185.995 | Y124: 17345.815 | Z124: 16840.18
A125: 2013 | B125: febrero | C125: 5444.1637 | D125: 209.651 | E125: 0 | F125: 2791.0158 | G125: 0 | H125: 7370.0845 | I125: 0 | K125: 15814.915 | M125: 3351.4344 | N125: 2649.6715 | O125: 1390.4082 | P125: 3850.4811 | Q125: 1480.9656 | S125: 2151.8424 | T125: 14874.803 | V125: 0 | X125: 30689.718 | Y125: 14874.803 | Z125: 15814.915
A126: 2013 | B126: marzo | C126: 6417.2595 | D126: 362.4 | E126: 0 | F126: 3054.2709 | G126: 0 | H126: 8583.623 | I126: 181.25003 | K126: 18598.803 | M126: 2341.1771 | N126: 2674.8511 | O126: 1644.6721 | P126: 3530.8336 | Q126: 1858.2212 | S126: 2325.6391 | T126: 14375.394 | V126: 0 | X126: 32974.198 | Y126: 14375.394 | Z126: 18598.803
A127: 2013 | B127: abril | C127: 6566.25 | D127: 180.20732 | E127: 238.66012 | F127: 3304.9262 | G127: 0 | H127: 8049.5581 | I127: 0 | K127: 18339.602 | M127: 2295.9286 | N127: 2510.8613 | O127: 2333.1585 | P127: 2380.9906 | Q127: 2228.0684 | S127: 1742.7574 | T127: 13491.765 | V127: 0 | X127: 31831.367 | Y127: 13491.765 | Z127: 18339.602
A128: 2013 | B128: mayo | C128: 5969.357 | D128: 187.78698 | E128: 183.0352 | F128: 3787.9822 | G128: 0 | H128: 7271.4338 | I128: 0 | K128: 17399.595 | M128: 3201.7874 | N128: 2663.6062 | O128: 919.28849 | P128: 1740.3987 | Q128: 923.4504 | S128: 2657.0045 | T128: 12105.536 | V128: 0 | X128: 29505.131 | Y128: 12105.536 | Z128: 17399.595
A129: 2013 | B129: junio | C129: 5433.9353 | D129: 119.14898 | E129: 256.51767 | F129: 3148.5616 | G129: 0 | H129: 6889.4783 | I129: 0 | K129: 15847.642 | M129: 3180.7073 | N129: 2829.2953 | O129: 913.29107 | P129: 4045.2379 | Q129: 821.75808 | S129: 2244.1209 | T129: 14034.411 | V129: 0 | X129: 29882.052 | Y129: 14034.411 | Z129: 15847.642
A130: 2013 | B130: julio | C130: 5734.5527 | D130: 0 | E130: 288.85384 | F130: 3560.5386 | G130: 0 | H130: 6215.8402 | I130: 125.31417 | K130: 15925.099 | M130: 2755.9241 | N130: 3946.5298 | O130: 916.23589 | P130: 1645.3835 | Q130: 1824.8494 | S130: 3034.9423 | T130: 14123.865 | V130: 0 | X130: 30048.964 | Y130: 14123.865 | Z130: 15925.099
A131: 2013 | B131: agosto | C131: 3635.28 | D131: 0 | E131: 310.3278 | F131: 4118.6093 | G131: 0 | H131: 5900.5203 | I131: 147.42832 | K131: 14112.166 | M131: 3586.1926 | N131: 1949.3406 | O131: 2688.5907 | P131: 2533.6446 | Q131: 1766.631 | S131: 2302.7995 | T131: 14827.199 | V131: 0 | X131: 28939.365 | Y131: 14827.199 | Z131: 14112.166
A132: 2013 | B132: septiembre | C132: 5401.0485 | D132: 229.80329 | E132: 295.34485 | F132: 3736.3269 | G132: 0 | H132: 4524.6773 | I132: 0 | K132: 14187.201 | M132: 2311.3785 | N132: 1819.2607 | O132: 2776.768 | P132: 5304.879 | Q132: 1915.6118 | S132: 3984.6414 | T132: 18112.539 | V132: 0 | X132: 32299.74 | Y132: 18112.539 | Z132: 14187.201
A133: 2013 | B133: octubre | C133: 6856.2397 | D133: 31.33125 | E133: 283.90415 | F133: 3084.0319 | G133: 0 | H133: 6388.2537 | I133: 0 | K133: 16643.761 | M133: 1780.347 | N133: 1704.161 | O133: 1823.0005 | P133: 2511.2919 | Q133: 1102.1792 | S133: 2009.1505 | T133: 10930.13 | V133: 0 | X133: 27573.891 | Y133: 10930.13 | Z133: 16643.761
A134: 2013 | B134: noviembre | C134: 6820.8301 | D134: 0 | E134: 0 | F134: 4084.9781 | G134: 0 | H134: 7658.9775 | I134: 0 | K134: 18564.786 | M134: 4720.3775 | N134: 1828.9204 | O134: 894.33844 | P134: 4205.0656 | Q134: 1930.1291 | S134: 2691.1782 | T134: 16270.009 | V134: 0 | X134: 34834.795 | Y134: 16270.009 | Z134: 18564.786
A135: 2013 | B135: diciembre | C135: 6829.623 | D135: 0 | E135: 0 | F135: 4691.419 | G135: 0 | H135: 7763.707 | I135: 24.64625 | K135: 19309.395 | M135: 1805.8819 | N135: 3053.2196 | O135: 2733.554 | P135: 2059.8206 | Q135: 871.52358 | S135: 2926.8409 | T135: 13450.841 | V135: 0 | X135: 32760.236 | Y135: 13450.841 | Z135: 19309.395
A136: 2013 | B136: total | C136: 70174.003 | D136: 1437.8288 | E136: 1856.6436 | F136: 42446.088 | G136: 0 | H136: 85189.941 | I136: 478.63877 | J136: 0 | K136: 201583.14 | M136: 37380.327 | N136: 30265.264 | O136: 20634.701 | P136: 37435.513 | Q136: 18395.73 | S136: 29830.771 | T136: 173942.31 | V136: 0 | X136: 375525.29 | Y136: 173942.31 | Z136: 201583.14
A137: 2014 | B137: enero | C137: 6976.1964 | D137: 0 | E137: 0 | F137: 3546.92 | G137: 0 | H137: 7759.2386 | I137: 157.34804 | J137: 0 | K137: 18439.703 | M137: 6181.9963 | N137: 2131.3669 | O137: 1776.4733 | P137: 3674.6818 | Q137: 1398.0414 | S137: 3360.0505 | T137: 18522.61 | V137: 0 | X137: 36962.313 | Y137: 18522.61 | Z137: 18439.703
A138: 2014 | B138: febrero | C138: 6480.3885 | D138: 0 | E138: 0 | F138: 4179.5659 | G138: 0 | H138: 7495.2864 | I138: 0 | J138: 0 | K138: 18155.241 | M138: 5489.8151 | N138: 835.71417 | O138: 2738.921 | P138: 2298.1528 | Q138: 1805.5143 | S138: 1782.8977 | T138: 14951.015 | V138: 0 | X138: 33106.256 | Y138: 14951.015 | Z138: 18155.241
A139: 2014 | B139: marzo | C139: 6885.6757 | D139: 0 | E139: 0 | F139: 3811.2181 | G139: 0 | H139: 7678.7892 | I139: 0 | J139: 0 | K139: 18375.683 | M139: 1342.0134 | N139: 2766.1186 | O139: 2303.6241 | P139: 4350.7961 | Q139: 2824.7163 | S139: 1777.4426 | T139: 15364.711 | V139: 0 | X139: 33740.394 | Y139: 15364.711 | Z139: 18375.683
A140: 2014 | B140: abril | C140: 6105.5317 | D140: 0 | E140: 299.70069 | F140: 3187.5067 | G140: 0 | H140: 6021.1013 | I140: 0 | J140: 0 | K140: 15613.84 | M140: 3119.5449 | N140: 846.2153 | O140: 3692.8087 | P140: 4123.5908 | Q140: 1804.553 | S140: 3831.4618 | T140: 17418.175 | V140: 0 | X140: 33032.015 | Y140: 17418.175 | Z140: 15613.84
A141: 2014 | B141: mayo | C141: 5861.7961 | D141: 0 | E141: 303.14809 | F141: 3737.7099 | G141: 0 | H141: 6341.1698 | I141: 0 | J141: 0 | K141: 16243.824 | M141: 1812.0341 | N141: 854.49618 | O141: 2312.7435 | P141: 3781.5564 | Q141: 859.60534 | S141: 2683.0752 | T141: 12303.511 | V141: 0 | X141: 28547.335 | Y141: 12303.511 | Z141: 16243.824
A142: 2014 | B142: junio | C142: 6132.95 | D142: 0 | E142: 298.19903 | F142: 3080.252 | G142: 0 | H142: 7010.5872 | I142: 0 | J142: 0 | K142: 16521.988 | M142: 1717.9572 | N142: 1911.9018 | O142: 891.22424 | P142: 1704.7321 | Q142: 1376.8647 | S142: 3743.2388 | T142: 11345.919 | V142: 0 | X142: 27867.907 | Y142: 11345.919 | Z142: 16521.988
A143: 2014 | B143: julio | C143: 4622.0045 | D143: 0 | E143: 300.9225 | F143: 3945.8859 | G143: 0 | H143: 7694.4964 | I143: 0 | J143: 0 | K143: 16563.309 | M143: 3535.5726 | N143: 1712.3263 | O143: 1927.0518 | P143: 2672.0636 | Q143: 1060.9944 | S143: 3533.05 | T143: 14441.059 | V143: 0 | X143: 31004.368 | Y143: 14441.059 | Z143: 16563.309
A144: 2014 | B144: agosto | C144: 4428.0447 | D144: 0 | E144: 310.00001 | F144: 4123.1274 | G144: 0 | H144: 5580.4077 | I144: 0 | J144: 0 | K144: 14441.58 | M144: 3908.0386 | N144: 1069.4406 | O144: 2088.879 | P144: 2278.1869 | Q144: 2524.3562 | S144: 1934.7306 | T144: 13803.632 | V144: 0 | X144: 28245.212 | Y144: 13803.632 | Z144: 14441.58
A145: 2014 | B145: septiembre | C145: 5991.8244 | D145: 0 | E145: 297.08839 | F145: 3852.6424 | G145: 0 | H145: 6621.9341 | I145: 0 | J145: 0 | K145: 16763.489 | M145: 892.88165 | N145: 1779.1802 | O145: 2811.0832 | P145: 4368.6482 | Q145: 2405.6236 | S145: 3340.492 | T145: 15597.909 | V145: 0 | X145: 32361.398 | Y145: 15597.909 | Z145: 16763.489
A146: 2014 | B146: octubre | C146: 6752.8634 | D146: 0 | E146: 0 | F146: 0 | G146: 0 | H146: 7043.3579 | I146: 0 | J146: 4522.2619 | K146: 18318.483 | M146: 4447.7585 | N146: 922.01744 | O146: 2720.2396 | P146: 3965.899 | Q146: 1658.3494 | S146: 4014.0422 | T146: 17728.306 | V146: 1.30259 | X146: 36048.092 | Y146: 17729.609 | Z146: 18318.483
...
