Workbook

Sheet Inicio
C4: Exportaciones de gas natural por puntos de salida
C9: Fuente/Notas | D9: enero 2010-actualidad | E9: Anejos de la Resolución del 15 de diciembre 2008
D10: Desde octubre 2014 | E10: De conformidad con la normativa europea, se agrupan las interconexiones en VIP Ibérico (Badajoz, Tuy y VIP Portugal) y VIP Pirineos (Irún y Larrau)
D11: enero 2015-actualidad | E11: Por adaptación a la legislación europea, desde enero de 2015, desaparece el concepto de contrato de tránsito de gas, tratándose en adelante como una importación y una exportación más. En consecuencia los datos de 2014 y 2015 no siempre son comparables.
D12: ^ mayor que 0
D13: * Se incluyen puestas en frío y suministro directo a buques consumidores
D14: Otras Salidas | E14: Se incluyen cisternas o asimilables cuyo punto de salida declarado no forma parte del sistema gasista.
A17: Actualizado el 13-07-2026 | G17: Para más información: cores.institucional@cores.es. Tlf.: +34 91 360 09 10, o visite: www.cores.es

Sheet Conexiones Internacionales
C3: =Inicio!C4 -> Exportaciones de gas natural por puntos de salida
A4: =Inicio!$A$17 -> Actualizado el 13-07-2026 | J4: Unidad: gigavatio hora
C5: Conexiones Internacionales
A6: Año | B6: Mes | C6: Badajoz | D6: Irún | E6: Larrau | F6: Tuy | G6: Zahara de los Atunes | H6: VIP Ibérico | I6: VIP Pirineos | J6: Total Conexiones internacionales
A7: 2010 | B7: enero | C7: 270.76523 | D7: 60.59545 | E7: 781.19584 | F7: 30.34069 | H7: 0 | J7: =SUM(C7:H7) -> 1142.8972
A8: 2010 | B8: febrero | C8: 308.13616 | D8: 55.20149 | E8: 692.55598 | F8: 18.11999 | H8: 0 | J8: =SUM(C8:H8) -> 1074.0136
A9: 2010 | B9: marzo | C9: 253.3749 | D9: 59.67474 | E9: 766.7584 | F9: 37.68241 | H9: 0 | J9: =SUM(C9:H9) -> 1117.4905
A10: 2010 | B10: abril | C10: 459.0939 | D10: 19.35017 | E10: 453.09244 | F10: 51.77132 | H10: 0 | J10: =SUM(C10:H10) -> 983.30783
A11: 2010 | B11: mayo | C11: 323.11179 | D11: 75.52084 | E11: 609.4359 | F11: 41.38473 | H11: 0 | J11: =SUM(C11:H11) -> 1049.4533
A12: 2010 | B12: junio | C12: 224.18412 | D12: 12.77312 | E12: 518.81647 | F12: 42.42245 | H12: 0 | J12: =SUM(C12:H12) -> 798.19616
A13: 2010 | B13: julio | C13: 573.78632 | D13: 37.29671 | E13: 458.54159 | F13: 51.45737 | H13: 0 | J13: =SUM(C13:H13) -> 1121.082
A14: 2010 | B14: agosto | C14: 456.72357 | D14: 63.68114 | E14: 36.20192 | F14: 36.42881 | H14: 0 | J14: =SUM(C14:H14) -> 593.03544
A15: 2010 | B15: septiembre | C15: 543.16841 | D15: 52.4967 | E15: 516.56062 | F15: 61.25829 | H15: 0 | J15: =SUM(C15:H15) -> 1173.484
A16: 2010 | B16: octubre | C16: 415.49789 | D16: 9.83148 | E16: 527.29605 | F16: 132.77559 | H16: 0 | J16: =SUM(C16:H16) -> 1085.401
A17: 2010 | B17: noviembre | C17: 492.70958 | D17: 52.25607 | E17: 570.93555 | F17: 151.8486 | H17: 0 | J17: =SUM(C17:H17) -> 1267.7498
A18: 2010 | B18: diciembre | C18: 688.90191 | D18: 54.22895 | E18: 648.55042 | F18: 63.869 | H18: 0 | J18: =SUM(C18:H18) -> 1455.5503
A19: 2010 | B19: total | C19: =SUM(C7:C18) -> 5009.4538 | D19: =SUM(D7:D18) -> 552.90686 | E19: =SUM(E7:E18) -> 6579.9412 | F19: =SUM(F7:F18) -> 719.35925 | H19: =SUM(H7:H18) -> 0 | J19: =SUM(C19:H19) -> 12861.661
A20: 2011 | B20: enero | C20: 482.33768 | D20: 58.27575 | E20: 791.14683 | F20: 63.524 | H20: 0 | J20: =SUM(C20:H20) -> 1395.2843
A21: 2011 | B21: febrero | C21: 677.18688 | D21: 25.50209 | E21: 448.73328 | F21: 91.78804 | H21: 0 | J21: =SUM(C21:H21) -> 1243.2103
A22: 2011 | B22: marzo | C22: 708.64171 | D22: 112.48378 | E22: 547.80054 | F22: 95.33067 | H22: 0 | J22: =SUM(C22:H22) -> 1464.2567
A23: 2011 | B23: abril | C23: 438.44445 | D23: 44.9982 | E23: 110.78866 | F23: 127.25466 | H23: 0 | J23: =SUM(C23:H23) -> 721.48597
A24: 2011 | B24: mayo | C24: 1095.2604 | D24: 70.79875 | E24: 213.23784 | F24: 197.22278 | H24: 0 | J24: =SUM(C24:H24) -> 1576.5198
A25: 2011 | B25: junio | C25: 371.72589 | D25: 0 | E25: 88.11402 | F25: 144.10911 | H25: 0 | J25: =SUM(C25:H25) -> 603.94902
A26: 2011 | B26: julio | C26: 299.347 | D26: 0 | E26: 35.667 | F26: 304.714 | H26: 0 | J26: =SUM(C26:H26) -> 639.728
A27: 2011 | B27: agosto | C27: 494.23203 | D27: 0 | E27: 0.15039 | F27: 277.14168 | H27: 0 | J27: =SUM(C27:H27) -> 771.5241
A28: 2011 | B28: septiembre | C28: 559.94 | D28: 0 | E28: 0 | F28: 312.58299 | H28: 0 | J28: =SUM(C28:H28) -> 872.52299
A29: 2011 | B29: octubre | C29: 379.67128 | D29: 68.62227 | E29: 0 | F29: 329.33467 | H29: 0 | J29: =SUM(C29:H29) -> 777.62822
A30: 2011 | B30: noviembre | C30: 194.75836 | D30: 0 | E30: 0 | F30: 298.22928 | H30: 0 | J30: =SUM(C30:H30) -> 492.98764
A31: 2011 | B31: diciembre | C31: 178.74949 | D31: 0 | E31: 0 | F31: 318.75 | H31: 0 | J31: =SUM(C31:H31) -> 497.49949
A32: 2011 | B32: total | C32: =SUM(C20:C31) -> 5880.2952 | D32: =SUM(D20:D31) -> 380.68084 | E32: =SUM(E20:E31) -> 2235.6386 | F32: =SUM(F20:F31) -> 2559.9819 | H32: =SUM(H20:H31) -> 0 | J32: =SUM(C32:H32) -> 11056.596
A33: 2012 | B33: enero | C33: 830.43385 | D33: 0 | E33: 0 | F33: 341.80641 | H33: 0 | J33: =SUM(C33:H33) -> 1172.2403
A34: 2012 | B34: febrero | C34: 707.38005 | D34: 5.74989 | E34: 24.83972 | F34: 282.31512 | H34: 0 | J34: =SUM(C34:H34) -> 1020.2848
A35: 2012 | B35: marzo | C35: 310.69936 | D35: 0 | E35: 0 | F35: 355.18083 | H35: 0 | J35: =SUM(C35:H35) -> 665.88019
A36: 2012 | B36: abril | C36: 280.35671 | D36: 0 | E36: 0 | F36: 270.6 | H36: 0 | J36: =SUM(C36:H36) -> 550.95671
A37: 2012 | B37: mayo | C37: 142.65174 | D37: 0 | E37: 0 | F37: 291.11 | H37: 0 | J37: =SUM(C37:H37) -> 433.76174
A38: 2012 | B38: junio | C38: 253.34 | D38: 0 | E38: 0 | F38: 250.85 | H38: 0 | J38: =SUM(C38:H38) -> 504.19
A39: 2012 | B39: julio | C39: 327.054 | D39: 0 | E39: 0 | F39: 346.8 | H39: 0 | J39: =SUM(C39:H39) -> 673.854
A40: 2012 | B40: agosto | C40: 352.5008 | D40: 0 | E40: 69.3 | F40: 251.5 | H40: 0 | J40: =SUM(C40:H40) -> 673.3008
A41: 2012 | B41: septiembre | C41: 446.7522 | D41: 0 | E41: 0 | F41: 291 | H41: 0 | J41: =SUM(C41:H41) -> 737.7522
A42: 2012 | B42: octubre | C42: 440.1176 | D42: 43.2642 | E42: 26.94989 | F42: 315.5 | H42: 0 | J42: =SUM(C42:H42) -> 825.83169
...

Sheet Plantas de regasificación
C3: =Inicio!C4 -> Exportaciones de gas natural por puntos de salida
A4: =Inicio!$A$17 -> Actualizado el 13-07-2026 | J4: Unidad: gigavatio hora
C5: Plantas de regasificación*
A6: Año | B6: Mes | C6: Barcelona | D6: Bilbao | E6: Cartagena | F6: Huelva | G6: Mugardos | H6: Musel | I6: Sagunto | J6: Total Plantas de regasificación
A7: 2010 | B7: enero | J7: =SUM(C7:I7) -> 0
A8: 2010 | B8: febrero | J8: =SUM(C8:I8) -> 0
A9: 2010 | B9: marzo | J9: =SUM(C9:I9) -> 0
A10: 2010 | B10: abril | J10: =SUM(C10:I10) -> 0
A11: 2010 | B11: mayo | J11: =SUM(C11:I11) -> 0
A12: 2010 | B12: junio | C12: 0.215 | E12: 0 | F12: 0 | G12: 0 | I12: 0 | J12: =SUM(C12:I12) -> 0.215
A13: 2010 | B13: julio | C13: 0.6094 | E13: 0 | F13: 0 | G13: 0 | I13: 0 | J13: =SUM(C13:I13) -> 0.6094
A14: 2010 | B14: agosto | C14: 0.512 | E14: 0 | F14: 49.29551 | G14: 0 | I14: 0 | J14: =SUM(C14:I14) -> 49.80751
A15: 2010 | B15: septiembre | C15: 0.422 | E15: 0 | F15: 0 | G15: 0 | I15: 0 | J15: =SUM(C15:I15) -> 0.422
A16: 2010 | B16: octubre | C16: 0.212 | E16: 0 | F16: 0 | G16: 0 | I16: 0 | J16: =SUM(C16:I16) -> 0.212
A17: 2010 | B17: noviembre | C17: 0.415 | E17: 0 | F17: 0 | G17: 0 | I17: 0 | J17: =SUM(C17:I17) -> 0.415
A18: 2010 | B18: diciembre | C18: 0.419 | E18: 0 | F18: 0 | G18: 0 | I18: 0 | J18: =SUM(C18:I18) -> 0.419
A19: 2010 | B19: total | C19: =SUM(C7:C18) -> 2.8044 | D19: =SUM(D7:D18) -> 0 | E19: =SUM(E7:E18) -> 0 | F19: =SUM(F7:F18) -> 49.29551 | G19: =SUM(G7:G18) -> 0 | I19: =SUM(I7:I18) -> 0 | J19: =SUM(C19:I19) -> 52.09991
A20: 2011 | B20: enero | C20: 0.424 | E20: 0 | F20: 0 | G20: 0 | J20: =SUM(C20:I20) -> 0.424
A21: 2011 | B21: febrero | C21: 0.412 | E21: 0 | F21: 459.89139 | G21: 0 | J21: =SUM(C21:I21) -> 460.30339
A22: 2011 | B22: marzo | C22: 0.334 | E22: 0 | F22: 469.37487 | G22: 0 | J22: =SUM(C22:I22) -> 469.70887
A23: 2011 | B23: abril | C23: 0.343 | E23: 0 | F23: 0 | G23: 5.19808 | J23: =SUM(C23:I23) -> 5.54108
A24: 2011 | B24: mayo | C24: 0.351 | E24: 0 | F24: 25.80237 | G24: 1007.4414 | J24: =SUM(C24:I24) -> 1033.5948
A25: 2011 | B25: junio | C25: 0.355 | E25: 166.45518 | F25: 0 | G25: 0 | J25: =SUM(C25:I25) -> 166.81018
A26: 2011 | B26: julio | C26: 0.363 | E26: 787.56273 | F26: 0 | G26: 0 | J26: =SUM(C26:I26) -> 787.92573
A27: 2011 | B27: agosto | C27: 0.49374 | E27: 0 | F27: 0 | G27: 0 | J27: =SUM(C27:I27) -> 0.49374
A28: 2011 | B28: septiembre | C28: 0.29515 | E28: 0 | F28: 473.93746 | G28: 959.72183 | J28: =SUM(C28:I28) -> 1433.9544
A29: 2011 | B29: octubre | C29: 0.154 | E29: 255.10653 | F29: 1123.3823 | G29: 468.88217 | J29: =SUM(C29:I29) -> 1847.525
A30: 2011 | B30: noviembre | C30: 0.35422 | E30: 463.04682 | F30: 0 | G30: 924.749 | J30: =SUM(C30:I30) -> 1388.15
A31: 2011 | B31: diciembre | C31: 0.157 | E31: 464.97312 | F31: 0 | G31: 0 | J31: =SUM(C31:I31) -> 465.13012
A32: 2011 | B32: total | C32: =SUM(C20:C31) -> 4.03611 | D32: =SUM(D20:D31) -> 0 | E32: =SUM(E20:E31) -> 2137.1444 | F32: =SUM(F20:F31) -> 2552.3884 | G32: =SUM(G20:G31) -> 3365.9925 | I32: =SUM(I20:I31) -> 0 | J32: =SUM(C32:I32) -> 8059.5613
A33: 2012 | B33: enero | C33: 0.52347 | E33: 227.8255 | F33: 777.1529 | G33: 36.23733 | I33: 0 | J33: =SUM(C33:I33) -> 1041.7392
A34: 2012 | B34: febrero | C34: 0.29347 | E34: 225.78379 | F34: 1079.6843 | G34: 0 | I34: 0 | J34: =SUM(C34:I34) -> 1305.7616
A35: 2012 | B35: marzo | C35: 0.88943 | E35: 913.13748 | F35: 1118.1564 | G35: 0 | I35: 0 | J35: =SUM(C35:I35) -> 2032.1833
A36: 2012 | B36: abril | C36: 0.85208 | E36: 1691.5741 | F36: 0 | G36: 1324.6153 | I36: 0 | J36: =SUM(C36:I36) -> 3017.0415
A37: 2012 | B37: mayo | C37: 1.11531 | E37: 815.13475 | F37: 2407.0028 | G37: 84.77999 | I37: 0 | J37: =SUM(C37:I37) -> 3308.0328
A38: 2012 | B38: junio | C38: 1.173 | E38: 990.60975 | F38: 1685.8826 | G38: 70.57424 | I38: 0 | J38: =SUM(C38:I38) -> 2748.2396
A39: 2012 | B39: julio | C39: 1.19856 | E39: 796.96444 | F39: 895.005 | G39: 2.64464 | I39: 0 | J39: =SUM(C39:I39) -> 1695.8126
A40: 2012 | B40: agosto | C40: 0.24782 | E40: 604.51108 | F40: 0 | G40: 971.29182 | I40: 0 | J40: =SUM(C40:I40) -> 1576.0507
A41: 2012 | B41: septiembre | C41: 0.86627 | E41: 0 | F41: 941.42101 | G41: 2.35275 | I41: 0 | J41: =SUM(C41:I41) -> 944.64003
A42: 2012 | B42: octubre | C42: 1.87436 | E42: 2408.0159 | F42: 0 | G42: 937.61527 | I42: 0 | J42: =SUM(C42:I42) -> 3347.5056
...

Sheet Todos
C3: =Inicio!C4 -> Exportaciones de gas natural por puntos de salida
A4: =Inicio!$A$17 -> Actualizado el 13-07-2026 | Y4: Unidad: gigavatio hora
C5: ='Conexiones Internacionales'!C5:L5 -> Conexiones Internacionales | L5: ='Plantas de regasificación'!C5 -> Plantas de regasificación* | W5: Total | X5: Total GNL | Y5: Total GN
A6: Año | B6: Mes | C6: ='Conexiones Internacionales'!C6 -> Badajoz | D6: ='Conexiones Internacionales'!D6 -> Irún | E6: ='Conexiones Internacionales'!E6 -> Larrau | F6: ='Conexiones Internacionales'!F6 -> Tuy | G6: Zahara de los Atunes | H6: ='Conexiones Internacionales'!H6 -> VIP Ibérico | I6: ='Conexiones Internacionales'!I6 -> VIP Pirineos | J6: ='Conexiones Internacionales'!J6 -> Total Conexiones internacionales | L6: ='Plantas de regasificación'!C6 -> Barcelona | M6: ='Plantas de regasificación'!D6 -> Bilbao | N6: ='Plantas de regasificación'!E6 -> Cartagena | O6: ='Plantas de regasificación'!F6 -> Huelva | P6: ='Plantas de regasificación'!G6 -> Mugardos | Q6: Musel | R6: ='Plantas de regasificación'!I6 -> Sagunto | S6: ='Plantas de regasificación'!J6 -> Total Plantas de regasificación | U6: Otras Salidas
A7: 2010 | B7: enero | C7: 270.76523 | D7: 60.59545 | E7: 781.19584 | F7: 30.34069 | H7: 0 | I7: 0 | J7: 1142.8972 | L7: 0 | M7: 0 | N7: 0 | O7: 0 | P7: 0 | R7: 0 | S7: 0 | W7: 1142.8972 | X7: 0 | Y7: 1142.8972
A8: 2010 | B8: febrero | C8: 308.13616 | D8: 55.20149 | E8: 692.55598 | F8: 18.11999 | H8: 0 | I8: 0 | J8: 1074.0136 | L8: 0 | M8: 0 | N8: 0 | O8: 0 | P8: 0 | R8: 0 | S8: 0 | W8: 1074.0136 | X8: 0 | Y8: 1074.0136
A9: 2010 | B9: marzo | C9: 253.3749 | D9: 59.67474 | E9: 766.7584 | F9: 37.68241 | H9: 0 | I9: 0 | J9: 1117.4905 | L9: 0 | M9: 0 | N9: 0 | O9: 0 | P9: 0 | R9: 0 | S9: 0 | W9: 1117.4905 | X9: 0 | Y9: 1117.4905
A10: 2010 | B10: abril | C10: 459.0939 | D10: 19.35017 | E10: 453.09244 | F10: 51.77132 | H10: 0 | I10: 0 | J10: 983.30783 | L10: 0 | M10: 0 | N10: 0 | O10: 0 | P10: 0 | R10: 0 | S10: 0 | W10: 983.30783 | X10: 0 | Y10: 983.30783
A11: 2010 | B11: mayo | C11: 323.11179 | D11: 75.52084 | E11: 609.4359 | F11: 41.38473 | H11: 0 | I11: 0 | J11: 1049.4533 | L11: 0 | M11: 0 | N11: 0 | O11: 0 | P11: 0 | R11: 0 | S11: 0 | W11: 1049.4533 | X11: 0 | Y11: 1049.4533
A12: 2010 | B12: junio | C12: 224.18412 | D12: 12.77312 | E12: 518.81647 | F12: 42.42245 | H12: 0 | I12: 0 | J12: 798.19616 | L12: 0.215 | M12: 0 | N12: 0 | O12: 0 | P12: 0 | R12: 0 | S12: 0.215 | W12: 798.41116 | X12: 0.215 | Y12: 798.19616
A13: 2010 | B13: julio | C13: 573.78632 | D13: 37.29671 | E13: 458.54159 | F13: 51.45737 | H13: 0 | I13: 0 | J13: 1121.082 | L13: 0.6094 | M13: 0 | N13: 0 | O13: 0 | P13: 0 | R13: 0 | S13: 0.6094 | W13: 1121.6914 | X13: 0.6094 | Y13: 1121.082
A14: 2010 | B14: agosto | C14: 456.72357 | D14: 63.68114 | E14: 36.20192 | F14: 36.42881 | H14: 0 | I14: 0 | J14: 593.03544 | L14: 0.512 | M14: 0 | N14: 0 | O14: 49.29551 | P14: 0 | R14: 0 | S14: 49.80751 | W14: 642.84295 | X14: 49.80751 | Y14: 593.03544
A15: 2010 | B15: septiembre | C15: 543.16841 | D15: 52.4967 | E15: 516.56062 | F15: 61.25829 | H15: 0 | I15: 0 | J15: 1173.484 | L15: 0.422 | M15: 0 | N15: 0 | O15: 0 | P15: 0 | R15: 0 | S15: 0.422 | W15: 1173.906 | X15: 0.422 | Y15: 1173.484
A16: 2010 | B16: octubre | C16: 415.49789 | D16: 9.83148 | E16: 527.29605 | F16: 132.77559 | H16: 0 | I16: 0 | J16: 1085.401 | L16: 0.212 | M16: 0 | N16: 0 | O16: 0 | P16: 0 | R16: 0 | S16: 0.212 | W16: 1085.613 | X16: 0.212 | Y16: 1085.401
A17: 2010 | B17: noviembre | C17: 492.70958 | D17: 52.25607 | E17: 570.93555 | F17: 151.8486 | H17: 0 | I17: 0 | J17: 1267.7498 | L17: 0.415 | M17: 0 | N17: 0 | O17: 0 | P17: 0 | R17: 0 | S17: 0.415 | W17: 1268.1648 | X17: 0.415 | Y17: 1267.7498
A18: 2010 | B18: diciembre | C18: 688.90191 | D18: 54.22895 | E18: 648.55042 | F18: 63.869 | H18: 0 | I18: 0 | J18: 1455.5503 | L18: 0.419 | M18: 0 | N18: 0 | O18: 0 | P18: 0 | R18: 0 | S18: 0.419 | W18: 1455.9693 | X18: 0.419 | Y18: 1455.5503
... A58: 2013 | B58: total | C58: 593.00355 | D58: 0 | E58: 4966.9136 | F58: 3367.9602 | H58: 1581.5507 | I58: 0 | J58: 10509.428 | L58: 66.10735 | M58: 0 | N58: 4711.374 | O58: 11398.436 | P58: 3292.0326 | R58: 12312.011 | S58: 31779.962 | W58: 42289.39 | X58: 31779.962 | Y58: 10509.428
A59: 2014 | B59: enero | C59: 32.2 | D59: 0 | E59: 158.17648 | F59: 271.6 | G59: 0 | H59: 215.72271 | I59: 0 | J59: 677.69919 | L59: 11.17453 | M59: 0 | N59: 0 | O59: 0 | P59: 2.71008 | R59: 965.96781 | S59: 979.85242 | U59: 0 | W59: 1657.5516 | X59: 979.85242 | Y59: 677.69919
A60: 2014 | B60: febrero | C60: 30.2 | D60: 0 | E60: 11.74044 | F60: 282.3 | G60: 0 | H60: 103.6 | I60: 0 | J60: 427.84044 | L60: 13.36258 | M60: 0 | N60: 969.34901 | O60: 0 | P60: 84.11438 | R60: 1908.4151 | S60: 2975.241 | U60: 0 | W60: 3403.0815 | X60: 2975.241 | Y60: 427.84044
A61: 2014 | B61: marzo | C61: 33 | D61: 0 | E61: 81.83289 | F61: 310 | G61: 0 | H61: 270.01859 | I61: 0 | J61: 694.85148 | L61: 13.63789 | M61: 0 | N61: 1398.2414 | O61: 986.10781 | P61: 2653.0718 | R61: 1330.4476 | S61: 6381.5065 | U61: 0 | W61: 7076.358 | X61: 6381.5065 | Y61: 694.85148
A62: 2014 | B62: abril | C62: 32.2074 | D62: 0 | E62: 45.68856 | F62: 268.85 | G62: 0 | H62: 261 | I62: 0 | J62: 607.74596 | L62: 13.6569 | M62: 0 | N62: 3242.4239 | O62: 3077.187 | P62: 1271.0148 | R62: 851.26082 | S62: 8455.5434 | U62: 0 | W62: 9063.2893 | X62: 8455.5434 | Y62: 607.74596
A63: 2014 | B63: mayo | C63: 33.2923 | D63: 0 | E63: 30.47904 | F63: 286 | G63: 0 | H63: 268.97905 | I63: 0 | J63: 618.75039 | L63: 12.94889 | M63: 0 | N63: 2063.8511 | O63: 2860.8598 | P63: 3.39448 | R63: 3004.7349 | S63: 7945.7892 | U63: 0 | W63: 8564.5396 | X63: 7945.7892 | Y63: 618.75039
A64: 2014 | B64: junio | C64: 30.6792 | D64: 0 | E64: 41.1066 | F64: 299.1 | G64: 0 | H64: 219 | I64: 0 | J64: 589.8858 | L64: 12.11876 | M64: 0 | N64: 17.68644 | O64: 1866.8057 | P64: 941.25345 | R64: 2009.3286 | S64: 4847.193 | U64: 0 | W64: 5437.0788 | X64: 4847.193 | Y64: 589.8858
A65: 2014 | B65: julio | C65: 32.5282 | D65: 0 | E65: 17.77109 | F65: 290.7 | G65: 0 | H65: 83.7 | I65: 0 | J65: 424.69929 | L65: 12.98165 | M65: 0 | N65: 1908.2176 | O65: 63.30867 | P65: 3.08614 | R65: 853.00579 | S65: 2840.5998 | U65: 0 | W65: 3265.2991 | X65: 2840.5998 | Y65: 424.69929
A66: 2014 | B66: agosto | C66: 31.4433 | D66: 0 | E66: 0.5013 | F66: 252 | G66: 0 | H66: 84.01 | I66: 0 | J66: 367.9546 | L66: 11.04 | M66: 0 | N66: 1069.3006 | O66: 906.72641 | P66: 892.29725 | R66: 1203.9178 | S66: 4083.2821 | U66: 0 | W66: 4451.2367 | X66: 4083.2821 | Y66: 367.9546
A67: 2014 | B67: septiembre | C67: 32.547 | D67: 0 | E67: 15.14327 | F67: 226.95 | G67: 0 | H67: 81 | I67: 0 | J67: 355.64027 | L67: 1258.0403 | M67: 0 | N67: 1050.5652 | O67: 1940.0912 | P67: 1031.319 | R67: 1141.5678 | S67: 6421.5835 | U67: 0 | W67: 6777.2238 | X67: 6421.5835 | Y67: 355.64027
A68: 2014 | B68: octubre | C68: 47.74 | D68: 0 | E68: 0 | F68: 446.66524 | G68: 0 | H68: 157.7 | I68: 1.58411 | J68: 653.68935 | L68: 1089.8233 | N68: 1629.0714 | O68: 2175.9489 | P68: 3.1445 | R68: 3160.912 | S68: 8058.9001 | U68: 0 | W68: 8712.5895 | X68: 8058.9001 | Y68: 653.68935
A69: 2014 | B69: noviembre | C69: 508.53468 | D69: 0 | E69: 0 | F69: 0 | G69: 0 | H69: 126 | I69: 0 | J69: 634.53468 | L69: 16.181 | N69: 1166.5259 | O69: 1089.0075 | P69: 61.77821 | R69: 1958.5496 | S69: 4292.0422 | U69: 0 | W69: 4926.5769 | X69: 4292.0422 | Y69: 634.53468
A70: 2014 | B70: diciembre | C70: 51.94394 | D70: 0 | E70: 0 | F70: 0 | G70: 0 | H70: 560.25668 | I70: 0 | J70: 612.20062 | L70: 20.80816 | M70: 0 | N70: 1504.3292 | O70: 960.89065 | P70: 37.10834 | R70: 875.9788 | S70: 3399.1151 | U70: 0 | W70: 4011.3157 | X70: 3399.1151 | Y70: 612.20062
A71: 2014 | B71: total | C71: 896.31602 | D71: 0 | E71: 402.43967 | F71: 2934.1652 | G71: 0 | H71: 2430.987 | I71: 1.58411 | J71: 6665.4921 | L71: 2485.774 | M71: 0 | N71: 16019.562 | O71: 15926.934 | P71: 6984.2924 | R71: 19264.087 | S71: 60680.648 | U71: 0 | W71: 67346.14 | X71: 60680.648 | Y71: 6665.4921
A72: 2015 | B72: enero | C72: 47.74 | D72: 0 | E72: 0 | F72: 0 | G72: 0 | H72: 3046.5725 | I72: 0 | J72: 3094.3125 | L72: 1100.526 | M72: 0 | N72: 485.78696 | O72: 0.62947 | P72: 27.66915 | R72: 0.62687 | S72: 1615.2384 | U72: 0 | W72: 4709.5509 | X72: 1615.2384 | Y72: 3094.3125
A73: 2015 | B73: febrero | C73: 0 | D73: 0 | E73: 0 | F73: 0 | G73: 0 | H73: 1575.7578 | I73: 0.40104 | J73: 1576.1588 | L73: 35.507 | M73: 2.08402 | N73: 0 | O73: 1.4486 | P73: 2.99445 | R73: 0 | S73: 42.03407 | U73: 0 | W73: 1618.1929 | X73: 42.03407 | Y73: 1576.1588
A74: 2015 | B74: marzo | C74: 47.74 | D74: 0 | E74: 0 | F74: 0 | G74: 0 | H74: 1542.065 | I74: 15.37524 | J74: 1605.1802 | L74: 38.18672 | M74: 0 | N74: 1.78316 | O74: 83.3212 | P74: 15.33981 | R74: 20.21193 | S74: 158.84282 | U74: 0 | W74: 1764.0231 | X74: 158.84282 | Y74: 1605.1802
A75: 2015 | B75: abril | C75: 46.2 | D75: 0 | E75: 0 | F75: 0 | G75: 0 | H75: 2772.5616 | I75: 635.40648 | J75: 3454.168 | L75: 24.86498 | M75: 0 | N75: 0 | O75: 0 | P75: 2.74045 | R75: 1077.3327 | S75: 1104.9381 | U75: 0 | W75: 4559.1061 | X75: 1104.9381 | Y75: 3454.168
A76: 2015 | B76: mayo | C76: 47.74 | D76: 0 | E76: 0 | F76: 0 | G76: 0 | H76: 3098.7896 | I76: 642.93551 | J76: 3789.4651 | L76: 973.94732 | M76: 1203.5992 | N76: 0 | O76: 0 | P76: 19.17343 | R76: 1746.6106 | S76: 3943.3305 | U76: 0 | W76: 7732.7956 | X76: 3943.3305 | Y76: 3789.4651
A77: 2015 | B77: junio | C77: 46.2 | D77: 0 | E77: 0 | F77: 0 | G77: 0 | H77: 3673.3559 | I77: 535.39101 | J77: 4254.947 | L77: 26.65794 | M77: 0 | N77: 0 | O77: 1037.6206 | P77: 2.99969 | R77: 250.50045 | S77: 1317.7787 | U77: 0 | W77: 5572.7257 | X77: 1317.7787 | Y77: 4254.947
A78: 2015 | B78: julio | C78: 31 | D78: 0 | E78: 0 | F78: 0 | G78: 0 | H78: 3711.4361 | I78: 1334.1737 | J78: 5076.6098 | L78: 21.89677 | M78: 932.96761 | N78: 0 | O78: 7.66913 | P78: 2.47787 | R78: 782.54684 | S78: 1747.5582 | U78: 0 | W78: 6824.168 | X78: 1747.5582 | Y78: 5076.6098
A79: 2015 | B79: agosto | C79: 31 | D79: 0 | E79: 0 | F79: 0 | G79: 0 | H79: 3316.6493 | I79: 1103.908 | J79: 4451.5572 | L79: 17.16628 | M79: 907.85503 | N79: 608.25701 | O79: 36.14072 | P79: 3.09218 | R79: 1283.4519 | S79: 2855.9631 | U79: 0 | W79: 7307.5203 | X79: 2855.9631 | Y79: 4451.5572
A80: 2015 | B80: septiembre | C80: 30 | D80: 0 | E80: 0 | F80: 0 | G80: 0 | H80: 3409.1155 | I80: 1164.9458 | J80: 4604.0613 | L80: 403.35685 | M80: 3.58709 | N80: 0 | O80: 33.73163 | P80: 7.12359 | R80: 2.16658 | S80: 449.96574 | U80: 0 | W80: 5054.027 | X80: 449.96574 | Y80: 4604.0613
A81: 2015 | B81: octubre | C81: 47.74 | D81: 0 | E81: 0 | F81: 0 | G81: 0 | H81: 3005.245 | I81: 138.64069 | J81: 3191.6256 | L81: 26.53101 | M81: 4.42129 | N81: 0 | O81: 3.28088 | P81: 24.59889 | R81: 1.87446 | S81: 60.70653 | U81: 0 | W81: 3252.3322 | X81: 60.70653 | Y81: 3191.6256
...
